*** Starting uWSGI 2.0.19.1 (64bit) on [Tue Nov 24 15:49:59 2020] ***
compiled with version: 7.5.0 on 03 July 2020 10:45:03
os: Linux-3.10.0-957.el7.x86_64 #1 SMP Thu Nov 8 23:39:32 UTC 2018
nodename: bab826df95db
machine: x86_64
clock source: unix
detected number of CPU cores: 8
current working directory: /
writing pidfile to /tmp/app5-master.pid
detected binary path: /usr/local/bin/uwsgi
!!! no internal routing support, rebuild with pcre support !!!
uWSGI running as root, you can use --uid/--gid/--chroot options
*** WARNING: you are running uWSGI as root !!! (use the --uid flag) *** 
chdir() to /workspace/
your memory page size is 4096 bytes
detected max file descriptor number: 1048576
lock engine: pthread robust mutexes
thunder lock: disabled (you can enable it with --thunder-lock)
uwsgi socket 0 bound to TCP address :9005 fd 3
uWSGI running as root, you can use --uid/--gid/--chroot options
*** WARNING: you are running uWSGI as root !!! (use the --uid flag) *** 
Python version: 3.6.9 (default, Apr 18 2020, 01:56:04)  [GCC 8.4.0]
Python main interpreter initialized at 0x55ef539b4f40
uWSGI running as root, you can use --uid/--gid/--chroot options
*** WARNING: you are running uWSGI as root !!! (use the --uid flag) *** 
python threads support enabled
your server socket listen backlog is limited to 100 connections
your mercy for graceful operations on workers is 60 seconds
mapped 145808 bytes (142 KB) for 1 cores
*** Operational MODE: single process ***
WSGI app 0 (mountpoint='') ready in 0 seconds on interpreter 0x55ef539b4f40 pid: 8 (default app)
uWSGI running as root, you can use --uid/--gid/--chroot options
*** WARNING: you are running uWSGI as root !!! (use the --uid flag) *** 
*** uWSGI is running in multiple interpreter mode ***
spawned uWSGI master process (pid: 8)
spawned uWSGI worker 1 (pid: 11, cores: 1)
Python auto-reloader enabled
[uwsgi-python-reloader] module/file ./PJ83_db_api/settings.py has been modified
...gracefully killing workers...
Gracefully killing worker 1 (pid: 11)...
worker 1 buried after 1 seconds
binary reloading uWSGI...
chdir() to /
closing all non-uwsgi socket fds > 2 (max_fd = 1048576)...
found fd 3 mapped to socket 0 (:9005)
running /usr/local/bin/uwsgi
[uWSGI] getting INI configuration from /workspace/PJ83_db_api/uwsgi.ini
*** Starting uWSGI 2.0.19.1 (64bit) on [Tue Nov 24 07:58:39 2020] ***
compiled with version: 7.5.0 on 03 July 2020 10:45:03
os: Linux-3.10.0-957.el7.x86_64 #1 SMP Thu Nov 8 23:39:32 UTC 2018
nodename: bab826df95db
machine: x86_64
clock source: unix
detected number of CPU cores: 8
current working directory: /
detected binary path: /usr/local/bin/uwsgi
!!! no internal routing support, rebuild with pcre support !!!
uWSGI running as root, you can use --uid/--gid/--chroot options
*** WARNING: you are running uWSGI as root !!! (use the --uid flag) *** 
chdir() to /workspace/
your memory page size is 4096 bytes
detected max file descriptor number: 1048576
lock engine: pthread robust mutexes
thunder lock: disabled (you can enable it with --thunder-lock)
uwsgi socket 0 inherited INET address :9005 fd 3
uWSGI running as root, you can use --uid/--gid/--chroot options
*** WARNING: you are running uWSGI as root !!! (use the --uid flag) *** 
Python version: 3.6.9 (default, Apr 18 2020, 01:56:04)  [GCC 8.4.0]
Python main interpreter initialized at 0x56549481a620
uWSGI running as root, you can use --uid/--gid/--chroot options
*** WARNING: you are running uWSGI as root !!! (use the --uid flag) *** 
python threads support enabled
your server socket listen backlog is limited to 100 connections
your mercy for graceful operations on workers is 60 seconds
mapped 145808 bytes (142 KB) for 1 cores
*** Operational MODE: single process ***
Traceback (most recent call last):
  File "/workspace/PJ83_db_api/wsgi.py", line 16, in <module>
    application = get_wsgi_application()
  File "/usr/local/lib/python3.6/dist-packages/django/core/wsgi.py", line 12, in get_wsgi_application
    django.setup(set_prefix=False)
  File "/usr/local/lib/python3.6/dist-packages/django/__init__.py", line 19, in setup
    configure_logging(settings.LOGGING_CONFIG, settings.LOGGING)
  File "/usr/local/lib/python3.6/dist-packages/django/conf/__init__.py", line 79, in __getattr__
    self._setup(name)
  File "/usr/local/lib/python3.6/dist-packages/django/conf/__init__.py", line 66, in _setup
    self._wrapped = Settings(settings_module)
  File "/usr/local/lib/python3.6/dist-packages/django/conf/__init__.py", line 157, in __init__
    mod = importlib.import_module(self.SETTINGS_MODULE)
  File "/usr/lib/python3.6/importlib/__init__.py", line 126, in import_module
    return _bootstrap._gcd_import(name[level:], package, level)
  File "<frozen importlib._bootstrap>", line 994, in _gcd_import
  File "<frozen importlib._bootstrap>", line 971, in _find_and_load
  File "<frozen importlib._bootstrap>", line 955, in _find_and_load_unlocked
  File "<frozen importlib._bootstrap>", line 665, in _load_unlocked
  File "<frozen importlib._bootstrap_external>", line 674, in exec_module
  File "<frozen importlib._bootstrap_external>", line 781, in get_code
  File "<frozen importlib._bootstrap_external>", line 741, in source_to_code
  File "<frozen importlib._bootstrap>", line 219, in _call_with_frames_removed
  File "./PJ83_db_api/settings.py", line 123
    AUTH_PASSWORD_VALIDATORS = [
                           ^
SyntaxError: invalid syntax
unable to load app 0 (mountpoint='') (callable not found or import error)
*** no app loaded. going in full dynamic mode ***
uWSGI running as root, you can use --uid/--gid/--chroot options
*** WARNING: you are running uWSGI as root !!! (use the --uid flag) *** 
*** uWSGI is running in multiple interpreter mode ***
gracefully (RE)spawned uWSGI master process (pid: 8)
spawned uWSGI worker 1 (pid: 35, cores: 1)
Python auto-reloader enabled
--- no python application found, check your startup logs for errors ---
[pid: 35|app: -1|req: -1/1] 10.10.3.222 () {34 vars in 495 bytes} [Tue Nov 24 09:11:27 2020] POST /api/mysql/domaintestlog/c/ => generated 21 bytes in 0 msecs (HTTP/1.1 500) 2 headers in 83 bytes (0 switches on core 0)
--- no python application found, check your startup logs for errors ---
[pid: 35|app: -1|req: -1/2] 10.10.3.222 () {34 vars in 495 bytes} [Tue Nov 24 09:11:58 2020] POST /api/mysql/domaintestlog/c/ => generated 21 bytes in 0 msecs (HTTP/1.1 500) 2 headers in 83 bytes (0 switches on core 0)
*** Starting uWSGI 2.0.19.1 (64bit) on [Tue Nov 24 17:14:04 2020] ***
compiled with version: 7.5.0 on 03 July 2020 10:45:03
os: Linux-3.10.0-957.el7.x86_64 #1 SMP Thu Nov 8 23:39:32 UTC 2018
nodename: 6d6f3bb79178
machine: x86_64
clock source: unix
detected number of CPU cores: 8
current working directory: /
writing pidfile to /tmp/app5-master.pid
detected binary path: /usr/local/bin/uwsgi
!!! no internal routing support, rebuild with pcre support !!!
uWSGI running as root, you can use --uid/--gid/--chroot options
*** WARNING: you are running uWSGI as root !!! (use the --uid flag) *** 
chdir() to /workspace/
your memory page size is 4096 bytes
detected max file descriptor number: 1048576
lock engine: pthread robust mutexes
thunder lock: disabled (you can enable it with --thunder-lock)
uwsgi socket 0 bound to TCP address :9005 fd 3
uWSGI running as root, you can use --uid/--gid/--chroot options
*** WARNING: you are running uWSGI as root !!! (use the --uid flag) *** 
Python version: 3.6.9 (default, Apr 18 2020, 01:56:04)  [GCC 8.4.0]
Python main interpreter initialized at 0x55c28b54ff40
uWSGI running as root, you can use --uid/--gid/--chroot options
*** WARNING: you are running uWSGI as root !!! (use the --uid flag) *** 
python threads support enabled
your server socket listen backlog is limited to 100 connections
your mercy for graceful operations on workers is 60 seconds
mapped 145808 bytes (142 KB) for 1 cores
*** Operational MODE: single process ***
Traceback (most recent call last):
  File "/workspace/PJ83_db_api/wsgi.py", line 16, in <module>
    application = get_wsgi_application()
  File "/usr/local/lib/python3.6/dist-packages/django/core/wsgi.py", line 12, in get_wsgi_application
    django.setup(set_prefix=False)
  File "/usr/local/lib/python3.6/dist-packages/django/__init__.py", line 24, in setup
    apps.populate(settings.INSTALLED_APPS)
  File "/usr/local/lib/python3.6/dist-packages/django/apps/registry.py", line 114, in populate
    app_config.import_models()
  File "/usr/local/lib/python3.6/dist-packages/django/apps/config.py", line 211, in import_models
    self.models_module = import_module(models_module_name)
  File "/usr/lib/python3.6/importlib/__init__.py", line 126, in import_module
    return _bootstrap._gcd_import(name[level:], package, level)
  File "<frozen importlib._bootstrap>", line 994, in _gcd_import
  File "<frozen importlib._bootstrap>", line 971, in _find_and_load
  File "<frozen importlib._bootstrap>", line 955, in _find_and_load_unlocked
  File "<frozen importlib._bootstrap>", line 665, in _load_unlocked
  File "<frozen importlib._bootstrap_external>", line 678, in exec_module
  File "<frozen importlib._bootstrap>", line 219, in _call_with_frames_removed
  File "/usr/local/lib/python3.6/dist-packages/django/contrib/auth/models.py", line 2, in <module>
    from django.contrib.auth.base_user import AbstractBaseUser, BaseUserManager
  File "/usr/local/lib/python3.6/dist-packages/django/contrib/auth/base_user.py", line 47, in <module>
    class AbstractBaseUser(models.Model):
  File "/usr/local/lib/python3.6/dist-packages/django/db/models/base.py", line 117, in __new__
    new_class.add_to_class('_meta', Options(meta, app_label))
  File "/usr/local/lib/python3.6/dist-packages/django/db/models/base.py", line 321, in add_to_class
    value.contribute_to_class(cls, name)
  File "/usr/local/lib/python3.6/dist-packages/django/db/models/options.py", line 204, in contribute_to_class
    self.db_table = truncate_name(self.db_table, connection.ops.max_name_length())
  File "/usr/local/lib/python3.6/dist-packages/django/db/__init__.py", line 28, in __getattr__
    return getattr(connections[DEFAULT_DB_ALIAS], item)
  File "/usr/local/lib/python3.6/dist-packages/django/db/utils.py", line 198, in __getitem__
    self.ensure_defaults(alias)
  File "/usr/local/lib/python3.6/dist-packages/django/db/utils.py", line 166, in ensure_defaults
    conn = self.databases[alias]
  File "/usr/local/lib/python3.6/dist-packages/django/utils/functional.py", line 80, in __get__
    res = instance.__dict__[self.name] = self.func(instance)
  File "/usr/local/lib/python3.6/dist-packages/django/db/utils.py", line 155, in databases
    raise ImproperlyConfigured("You must define a '%s' database." % DEFAULT_DB_ALIAS)
django.core.exceptions.ImproperlyConfigured: You must define a 'default' database.
unable to load app 0 (mountpoint='') (callable not found or import error)
*** no app loaded. going in full dynamic mode ***
uWSGI running as root, you can use --uid/--gid/--chroot options
*** WARNING: you are running uWSGI as root !!! (use the --uid flag) *** 
*** uWSGI is running in multiple interpreter mode ***
spawned uWSGI master process (pid: 8)
spawned uWSGI worker 1 (pid: 11, cores: 1)
Python auto-reloader enabled
--- no python application found, check your startup logs for errors ---
[pid: 11|app: -1|req: -1/1] 10.10.3.222 () {34 vars in 495 bytes} [Tue Nov 24 09:17:47 2020] POST /api/mysql/domaintestlog/c/ => generated 21 bytes in 0 msecs (HTTP/1.1 500) 2 headers in 83 bytes (0 switches on core 0)
[uwsgi-python-reloader] module/file ./PJ83_db_api/settings.py has been modified
...gracefully killing workers...
Gracefully killing worker 1 (pid: 11)...
worker 1 buried after 1 seconds
binary reloading uWSGI...
chdir() to /
closing all non-uwsgi socket fds > 2 (max_fd = 1048576)...
found fd 3 mapped to socket 0 (:9005)
running /usr/local/bin/uwsgi
[uWSGI] getting INI configuration from /workspace/PJ83_db_api/uwsgi.ini
*** Starting uWSGI 2.0.19.1 (64bit) on [Tue Nov 24 09:21:12 2020] ***
compiled with version: 7.5.0 on 03 July 2020 10:45:03
os: Linux-3.10.0-957.el7.x86_64 #1 SMP Thu Nov 8 23:39:32 UTC 2018
nodename: 6d6f3bb79178
machine: x86_64
clock source: unix
detected number of CPU cores: 8
current working directory: /
detected binary path: /usr/local/bin/uwsgi
!!! no internal routing support, rebuild with pcre support !!!
uWSGI running as root, you can use --uid/--gid/--chroot options
*** WARNING: you are running uWSGI as root !!! (use the --uid flag) *** 
chdir() to /workspace/
your memory page size is 4096 bytes
detected max file descriptor number: 1048576
lock engine: pthread robust mutexes
thunder lock: disabled (you can enable it with --thunder-lock)
uwsgi socket 0 inherited INET address :9005 fd 3
uWSGI running as root, you can use --uid/--gid/--chroot options
*** WARNING: you are running uWSGI as root !!! (use the --uid flag) *** 
Python version: 3.6.9 (default, Apr 18 2020, 01:56:04)  [GCC 8.4.0]
Python main interpreter initialized at 0x55aef6ece620
uWSGI running as root, you can use --uid/--gid/--chroot options
*** WARNING: you are running uWSGI as root !!! (use the --uid flag) *** 
python threads support enabled
your server socket listen backlog is limited to 100 connections
your mercy for graceful operations on workers is 60 seconds
mapped 145808 bytes (142 KB) for 1 cores
*** Operational MODE: single process ***
WSGI app 0 (mountpoint='') ready in 0 seconds on interpreter 0x55aef6ece620 pid: 8 (default app)
uWSGI running as root, you can use --uid/--gid/--chroot options
*** WARNING: you are running uWSGI as root !!! (use the --uid flag) *** 
*** uWSGI is running in multiple interpreter mode ***
gracefully (RE)spawned uWSGI master process (pid: 8)
spawned uWSGI worker 1 (pid: 14, cores: 1)
Python auto-reloader enabled
*** Starting uWSGI 2.0.19.1 (64bit) on [Tue Nov 24 17:21:43 2020] ***
compiled with version: 7.5.0 on 03 July 2020 10:45:03
os: Linux-3.10.0-957.el7.x86_64 #1 SMP Thu Nov 8 23:39:32 UTC 2018
nodename: c2ec9cacbbef
machine: x86_64
clock source: unix
detected number of CPU cores: 8
current working directory: /
writing pidfile to /tmp/app5-master.pid
detected binary path: /usr/local/bin/uwsgi
!!! no internal routing support, rebuild with pcre support !!!
uWSGI running as root, you can use --uid/--gid/--chroot options
*** WARNING: you are running uWSGI as root !!! (use the --uid flag) *** 
chdir() to /workspace/
your memory page size is 4096 bytes
detected max file descriptor number: 1048576
lock engine: pthread robust mutexes
thunder lock: disabled (you can enable it with --thunder-lock)
uwsgi socket 0 bound to TCP address :9005 fd 3
uWSGI running as root, you can use --uid/--gid/--chroot options
*** WARNING: you are running uWSGI as root !!! (use the --uid flag) *** 
Python version: 3.6.9 (default, Apr 18 2020, 01:56:04)  [GCC 8.4.0]
Python main interpreter initialized at 0x55cde3e95f40
uWSGI running as root, you can use --uid/--gid/--chroot options
*** WARNING: you are running uWSGI as root !!! (use the --uid flag) *** 
python threads support enabled
your server socket listen backlog is limited to 100 connections
your mercy for graceful operations on workers is 60 seconds
mapped 145808 bytes (142 KB) for 1 cores
*** Operational MODE: single process ***
WSGI app 0 (mountpoint='') ready in 0 seconds on interpreter 0x55cde3e95f40 pid: 8 (default app)
uWSGI running as root, you can use --uid/--gid/--chroot options
*** WARNING: you are running uWSGI as root !!! (use the --uid flag) *** 
*** uWSGI is running in multiple interpreter mode ***
spawned uWSGI master process (pid: 8)
spawned uWSGI worker 1 (pid: 11, cores: 1)
Python auto-reloader enabled
Invalid HTTP_HOST header: '10.80.1.20:9005'. You may need to add '10.80.1.20' to ALLOWED_HOSTS.
Bad Request: /api/mysql/domaintestlog/c/
[pid: 11|app: 0|req: 1/1] 10.10.3.222 () {34 vars in 495 bytes} [Tue Nov 24 09:35:08 2020] POST /api/mysql/domaintestlog/c/ => generated 56088 bytes in 72 msecs (HTTP/1.1 400) 1 headers in 53 bytes (2 switches on core 0)
[uwsgi-python-reloader] module/file ./PJ83_db_api/settings.py has been modified
...gracefully killing workers...
Gracefully killing worker 1 (pid: 11)...
worker 1 buried after 1 seconds
binary reloading uWSGI...
chdir() to /
closing all non-uwsgi socket fds > 2 (max_fd = 1048576)...
found fd 3 mapped to socket 0 (:9005)
running /usr/local/bin/uwsgi
[uWSGI] getting INI configuration from /workspace/PJ83_db_api/uwsgi.ini
*** Starting uWSGI 2.0.19.1 (64bit) on [Tue Nov 24 09:35:35 2020] ***
compiled with version: 7.5.0 on 03 July 2020 10:45:03
os: Linux-3.10.0-957.el7.x86_64 #1 SMP Thu Nov 8 23:39:32 UTC 2018
nodename: c2ec9cacbbef
machine: x86_64
clock source: unix
detected number of CPU cores: 8
current working directory: /
detected binary path: /usr/local/bin/uwsgi
!!! no internal routing support, rebuild with pcre support !!!
uWSGI running as root, you can use --uid/--gid/--chroot options
*** WARNING: you are running uWSGI as root !!! (use the --uid flag) *** 
chdir() to /workspace/
your memory page size is 4096 bytes
detected max file descriptor number: 1048576
lock engine: pthread robust mutexes
thunder lock: disabled (you can enable it with --thunder-lock)
uwsgi socket 0 inherited INET address :9005 fd 3
uWSGI running as root, you can use --uid/--gid/--chroot options
*** WARNING: you are running uWSGI as root !!! (use the --uid flag) *** 
Python version: 3.6.9 (default, Apr 18 2020, 01:56:04)  [GCC 8.4.0]
Python main interpreter initialized at 0x55e82a163620
uWSGI running as root, you can use --uid/--gid/--chroot options
*** WARNING: you are running uWSGI as root !!! (use the --uid flag) *** 
python threads support enabled
your server socket listen backlog is limited to 100 connections
your mercy for graceful operations on workers is 60 seconds
mapped 145808 bytes (142 KB) for 1 cores
*** Operational MODE: single process ***
WSGI app 0 (mountpoint='') ready in 1 seconds on interpreter 0x55e82a163620 pid: 8 (default app)
uWSGI running as root, you can use --uid/--gid/--chroot options
*** WARNING: you are running uWSGI as root !!! (use the --uid flag) *** 
*** uWSGI is running in multiple interpreter mode ***
gracefully (RE)spawned uWSGI master process (pid: 8)
spawned uWSGI worker 1 (pid: 14, cores: 1)
Python auto-reloader enabled
Internal Server Error: /api/mysql/domaintestlog/c/
Traceback (most recent call last):
  File "/usr/local/lib/python3.6/dist-packages/django/core/handlers/exception.py", line 34, in inner
    response = get_response(request)
  File "/usr/local/lib/python3.6/dist-packages/django/core/handlers/base.py", line 115, in _get_response
    response = self.process_exception_by_middleware(e, request)
  File "/usr/local/lib/python3.6/dist-packages/django/core/handlers/base.py", line 113, in _get_response
    response = wrapped_callback(request, *callback_args, **callback_kwargs)
  File "/usr/local/lib/python3.6/dist-packages/django/views/decorators/csrf.py", line 54, in wrapped_view
    return view_func(*args, **kwargs)
  File "/usr/local/lib/python3.6/dist-packages/django/views/generic/base.py", line 71, in view
    return self.dispatch(request, *args, **kwargs)
  File "/usr/local/lib/python3.6/dist-packages/rest_framework/views.py", line 509, in dispatch
    response = self.handle_exception(exc)
  File "/usr/local/lib/python3.6/dist-packages/rest_framework/views.py", line 469, in handle_exception
    self.raise_uncaught_exception(exc)
  File "/usr/local/lib/python3.6/dist-packages/rest_framework/views.py", line 480, in raise_uncaught_exception
    raise exc
  File "/usr/local/lib/python3.6/dist-packages/rest_framework/views.py", line 506, in dispatch
    response = handler(request, *args, **kwargs)
  File "/usr/local/lib/python3.6/dist-packages/rest_framework/decorators.py", line 50, in handler
    return func(*args, **kwargs)
  File "./db_api/views.py", line 20, in C_data_DomainTestLog
    data_serializer.save()
  File "/usr/local/lib/python3.6/dist-packages/rest_framework/serializers.py", line 205, in save
    self.instance = self.create(validated_data)
  File "/usr/local/lib/python3.6/dist-packages/rest_framework/serializers.py", line 939, in create
    instance = ModelClass._default_manager.create(**validated_data)
  File "/usr/local/lib/python3.6/dist-packages/django/db/models/manager.py", line 82, in manager_method
    return getattr(self.get_queryset(), name)(*args, **kwargs)
  File "/usr/local/lib/python3.6/dist-packages/django/db/models/query.py", line 422, in create
    obj.save(force_insert=True, using=self.db)
  File "/usr/local/lib/python3.6/dist-packages/django/db/models/base.py", line 741, in save
    force_update=force_update, update_fields=update_fields)
  File "/usr/local/lib/python3.6/dist-packages/django/db/models/base.py", line 779, in save_base
    force_update, using, update_fields,
  File "/usr/local/lib/python3.6/dist-packages/django/db/models/base.py", line 870, in _save_table
    result = self._do_insert(cls._base_manager, using, fields, update_pk, raw)
  File "/usr/local/lib/python3.6/dist-packages/django/db/models/base.py", line 908, in _do_insert
    using=using, raw=raw)
  File "/usr/local/lib/python3.6/dist-packages/django/db/models/manager.py", line 82, in manager_method
    return getattr(self.get_queryset(), name)(*args, **kwargs)
  File "/usr/local/lib/python3.6/dist-packages/django/db/models/query.py", line 1186, in _insert
    return query.get_compiler(using=using).execute_sql(return_id)
  File "/usr/local/lib/python3.6/dist-packages/django/db/models/sql/compiler.py", line 1330, in execute_sql
    with self.connection.cursor() as cursor:
  File "/usr/local/lib/python3.6/dist-packages/django/db/backends/base/base.py", line 256, in cursor
    return self._cursor()
  File "/usr/local/lib/python3.6/dist-packages/django/db/backends/base/base.py", line 233, in _cursor
    self.ensure_connection()
  File "/usr/local/lib/python3.6/dist-packages/django/db/backends/base/base.py", line 217, in ensure_connection
    self.connect()
  File "/usr/local/lib/python3.6/dist-packages/django/db/backends/base/base.py", line 197, in connect
    self.init_connection_state()
  File "/usr/local/lib/python3.6/dist-packages/django/db/backends/mysql/base.py", line 231, in init_connection_state
    if self.features.is_sql_auto_is_null_enabled:
  File "/usr/local/lib/python3.6/dist-packages/django/utils/functional.py", line 80, in __get__
    res = instance.__dict__[self.name] = self.func(instance)
  File "/usr/local/lib/python3.6/dist-packages/django/db/backends/mysql/features.py", line 82, in is_sql_auto_is_null_enabled
    cursor.execute('SELECT @@SQL_AUTO_IS_NULL')
  File "/usr/local/lib/python3.6/dist-packages/django/db/backends/utils.py", line 103, in execute
    sql = self.db.ops.last_executed_query(self.cursor, sql, params)
  File "/usr/local/lib/python3.6/dist-packages/django/db/backends/mysql/operations.py", line 146, in last_executed_query
    query = query.decode(errors='replace')
AttributeError: 'str' object has no attribute 'decode'
[pid: 14|app: 0|req: 1/1] 10.10.3.222 () {34 vars in 495 bytes} [Tue Nov 24 09:35:41 2020] POST /api/mysql/domaintestlog/c/ => generated 16148 bytes in 336 msecs (HTTP/1.1 500) 4 headers in 153 bytes (1 switches on core 0)
*** Starting uWSGI 2.0.19.1 (64bit) on [Tue Nov 24 17:45:23 2020] ***
compiled with version: 7.5.0 on 03 July 2020 10:45:03
os: Linux-3.10.0-957.el7.x86_64 #1 SMP Thu Nov 8 23:39:32 UTC 2018
nodename: de0426a442bd
machine: x86_64
clock source: unix
detected number of CPU cores: 8
current working directory: /
writing pidfile to /tmp/app5-master.pid
detected binary path: /usr/local/bin/uwsgi
!!! no internal routing support, rebuild with pcre support !!!
uWSGI running as root, you can use --uid/--gid/--chroot options
*** WARNING: you are running uWSGI as root !!! (use the --uid flag) *** 
chdir() to /workspace/
your memory page size is 4096 bytes
detected max file descriptor number: 1048576
lock engine: pthread robust mutexes
thunder lock: disabled (you can enable it with --thunder-lock)
uwsgi socket 0 bound to TCP address :9005 fd 3
uWSGI running as root, you can use --uid/--gid/--chroot options
*** WARNING: you are running uWSGI as root !!! (use the --uid flag) *** 
Python version: 3.6.9 (default, Apr 18 2020, 01:56:04)  [GCC 8.4.0]
Python main interpreter initialized at 0x556a5af13f40
uWSGI running as root, you can use --uid/--gid/--chroot options
*** WARNING: you are running uWSGI as root !!! (use the --uid flag) *** 
python threads support enabled
your server socket listen backlog is limited to 100 connections
your mercy for graceful operations on workers is 60 seconds
mapped 145808 bytes (142 KB) for 1 cores
*** Operational MODE: single process ***
WSGI app 0 (mountpoint='') ready in 1 seconds on interpreter 0x556a5af13f40 pid: 8 (default app)
uWSGI running as root, you can use --uid/--gid/--chroot options
*** WARNING: you are running uWSGI as root !!! (use the --uid flag) *** 
*** uWSGI is running in multiple interpreter mode ***
spawned uWSGI master process (pid: 8)
spawned uWSGI worker 1 (pid: 11, cores: 1)
Python auto-reloader enabled
[pid: 11|app: 0|req: 1/1] 10.10.3.222 () {34 vars in 495 bytes} [Tue Nov 24 09:45:59 2020] POST /api/mysql/domaintestlog/c/ => generated 376 bytes in 221 msecs (HTTP/1.1 201) 5 headers in 158 bytes (1 switches on core 0)
Bad Request: /api/mysql/domaintestlog/c/
[pid: 11|app: 0|req: 2/2] 10.10.3.222 () {34 vars in 495 bytes} [Tue Nov 24 09:49:10 2020] POST /api/mysql/domaintestlog/c/ => generated 110 bytes in 6 msecs (HTTP/1.1 400) 5 headers in 162 bytes (1 switches on core 0)
[pid: 11|app: 0|req: 3/3] 10.10.3.222 () {34 vars in 495 bytes} [Tue Nov 24 09:49:43 2020] POST /api/mysql/domaintestlog/c/ => generated 563 bytes in 7 msecs (HTTP/1.1 201) 5 headers in 158 bytes (1 switches on core 0)
[pid: 11|app: 0|req: 4/4] 10.10.3.222 () {34 vars in 495 bytes} [Tue Nov 24 09:53:50 2020] POST /api/mysql/domaintestlog/c/ => generated 563 bytes in 8 msecs (HTTP/1.1 201) 5 headers in 158 bytes (1 switches on core 0)
Internal Server Error: /api/mysql/domaintestlog/d/4
Traceback (most recent call last):
  File "/usr/local/lib/python3.6/dist-packages/django/core/handlers/exception.py", line 34, in inner
    response = get_response(request)
  File "/usr/local/lib/python3.6/dist-packages/django/utils/deprecation.py", line 93, in __call__
    response = self.process_request(request)
  File "/usr/local/lib/python3.6/dist-packages/django/middleware/common.py", line 53, in process_request
    path = self.get_full_path_with_slash(request)
  File "/usr/local/lib/python3.6/dist-packages/django/middleware/common.py", line 93, in get_full_path_with_slash
    'url': request.get_host() + new_path,
RuntimeError: You called this URL via POST, but the URL doesn't end in a slash and you have APPEND_SLASH set. Django can't redirect to the slash URL while maintaining POST data. Change your form to point to 10.80.1.20:9005/api/mysql/domaintestlog/d/4/ (note the trailing slash), or set APPEND_SLASH=False in your Django settings.
[pid: 11|app: 0|req: 5/5] 10.10.3.222 () {34 vars in 497 bytes} [Tue Nov 24 09:54:54 2020] POST /api/mysql/domaintestlog/d/4 => generated 56909 bytes in 104 msecs (HTTP/1.1 500) 1 headers in 63 bytes (2 switches on core 0)
Method Not Allowed: /api/mysql/domaintestlog/d/4/
[pid: 11|app: 0|req: 6/6] 10.10.3.222 () {34 vars in 499 bytes} [Tue Nov 24 09:55:03 2020] POST /api/mysql/domaintestlog/d/4/ => generated 41 bytes in 2 msecs (HTTP/1.1 405) 5 headers in 170 bytes (1 switches on core 0)
Method Not Allowed: /api/mysql/domaintestlog/d/4/
[pid: 11|app: 0|req: 7/7] 10.10.3.222 () {34 vars in 498 bytes} [Tue Nov 24 09:55:10 2020] PUT /api/mysql/domaintestlog/d/4/ => generated 40 bytes in 3 msecs (HTTP/1.1 405) 5 headers in 170 bytes (1 switches on core 0)
[pid: 11|app: 0|req: 8/8] 10.10.3.222 () {34 vars in 501 bytes} [Tue Nov 24 09:55:27 2020] DELETE /api/mysql/domaintestlog/d/4/ => generated 45 bytes in 9 msecs (HTTP/1.1 204) 5 headers in 162 bytes (1 switches on core 0)
[pid: 11|app: 0|req: 9/9] 10.10.3.222 () {34 vars in 495 bytes} [Tue Nov 24 09:55:45 2020] DELETE /api/mysql/domaintestlog/r => generated 0 bytes in 2 msecs (HTTP/1.1 301) 3 headers in 132 bytes (1 switches on core 0)
Method Not Allowed: /api/mysql/domaintestlog/r/
[pid: 11|app: 0|req: 10/10] 10.10.3.222 () {34 vars in 497 bytes} [Tue Nov 24 09:55:49 2020] DELETE /api/mysql/domaintestlog/r/ => generated 43 bytes in 2 msecs (HTTP/1.1 405) 5 headers in 167 bytes (1 switches on core 0)
[pid: 11|app: 0|req: 11/11] 10.10.3.222 () {34 vars in 494 bytes} [Tue Nov 24 09:55:53 2020] GET /api/mysql/domaintestlog/r/ => generated 551 bytes in 9 msecs (HTTP/1.1 200) 5 headers in 152 bytes (1 switches on core 0)
[pid: 11|app: 0|req: 12/12] 10.10.3.222 () {34 vars in 496 bytes} [Tue Nov 24 09:56:36 2020] GET /api/mysql/domaintestlog/u/4 => generated 0 bytes in 3 msecs (HTTP/1.1 301) 3 headers in 134 bytes (1 switches on core 0)
Internal Server Error: /api/mysql/domaintestlog/u/4
Traceback (most recent call last):
  File "/usr/local/lib/python3.6/dist-packages/django/core/handlers/exception.py", line 34, in inner
    response = get_response(request)
  File "/usr/local/lib/python3.6/dist-packages/django/utils/deprecation.py", line 93, in __call__
    response = self.process_request(request)
  File "/usr/local/lib/python3.6/dist-packages/django/middleware/common.py", line 53, in process_request
    path = self.get_full_path_with_slash(request)
  File "/usr/local/lib/python3.6/dist-packages/django/middleware/common.py", line 93, in get_full_path_with_slash
    'url': request.get_host() + new_path,
RuntimeError: You called this URL via PUT, but the URL doesn't end in a slash and you have APPEND_SLASH set. Django can't redirect to the slash URL while maintaining PUT data. Change your form to point to 10.80.1.20:9005/api/mysql/domaintestlog/u/4/ (note the trailing slash), or set APPEND_SLASH=False in your Django settings.
[pid: 11|app: 0|req: 13/13] 10.10.3.222 () {34 vars in 496 bytes} [Tue Nov 24 09:56:39 2020] PUT /api/mysql/domaintestlog/u/4 => generated 56894 bytes in 98 msecs (HTTP/1.1 500) 1 headers in 63 bytes (2 switches on core 0)
[pid: 11|app: 0|req: 14/14] 10.10.3.222 () {34 vars in 494 bytes} [Tue Nov 24 09:57:14 2020] GET /api/mysql/domaintestlog/r/ => generated 551 bytes in 14 msecs (HTTP/1.1 200) 5 headers in 152 bytes (1 switches on core 0)
[pid: 11|app: 0|req: 15/15] 10.10.3.222 () {34 vars in 496 bytes} [Tue Nov 24 09:57:28 2020] GET /api/mysql/domaintestlog/u/3 => generated 0 bytes in 1 msecs (HTTP/1.1 301) 3 headers in 134 bytes (1 switches on core 0)
Method Not Allowed: /api/mysql/domaintestlog/u/3/
[pid: 11|app: 0|req: 16/16] 10.10.3.222 () {34 vars in 498 bytes} [Tue Nov 24 09:57:34 2020] GET /api/mysql/domaintestlog/u/3/ => generated 40 bytes in 4 msecs (HTTP/1.1 405) 5 headers in 167 bytes (1 switches on core 0)
[pid: 11|app: 0|req: 17/17] 10.10.3.222 () {34 vars in 498 bytes} [Tue Nov 24 09:57:38 2020] PUT /api/mysql/domaintestlog/u/3/ => generated 556 bytes in 19 msecs (HTTP/1.1 200) 5 headers in 152 bytes (1 switches on core 0)
